<?xml version='1.0'?>

<robot name="my_robot" xmlns:xacro="http://www.ros.org/wiki/xacro">
	
  <xacro:include filename="$(find my_robot)/urdf/my_robot.gazebo" />

  <xacro:property name="scale" value="1.0" />
  <xacro:property name="bot_l" value="${scale * 0.5}" />
  <xacro:property name="bot_w" value="${scale * 0.3}" />
  <xacro:property name="bot_h" value="${scale * 0.15}" />
  <xacro:property name="chassis_base_x_offset" value="0" />
  <xacro:property name="wheel_l" value="${scale * 0.095}" />
  <xacro:property name="wheel_r" value="${scale * 0.15}" />
  <xacro:property name="castor_r" value="${scale * 0.075}" />
  <xacro:property name="rear_wing_l" value="${scale * 0.05}" />
  <xacro:property name="rear_wing_w" value="${scale * 0.3}" />
  <xacro:property name="rear_wing_h" value="${scale * 0.075}" />
  
  <link name="robot_footprint"></link>

  <joint name="robot_footprint_joint" type="fixed">
    <origin xyz="0 0 0" rpy="0 0 0" />
    <parent link="robot_footprint"/>
    <child link="chassis" />
  </joint>

  <link name='chassis'>
    <pose>0 0 0.125 0 0 0</pose>

    <inertial>
      <mass value="15.0"/>
      <origin xyz="0.0 0 0" rpy="0 0 0"/>
      <inertia
          ixx="0.1" ixy="0" ixz="0"
          iyy="0.1" iyz="0"
          izz="0.1"
      />
    </inertial>

    <collision name='collision'>
      <origin xyz="0 0 0" rpy=" 0 0 0"/> 
      <geometry>
        <box size="${bot_l} ${bot_w} ${bot_h}"/>
      </geometry>
    </collision>

    <visual name='chassis_visual'>
      <origin xyz="0 0 0" rpy=" 0 0 0"/>
      <geometry>
        <box size="${bot_l} ${bot_w} ${bot_h}"/>
      </geometry>
    </visual>

    <collision name='back_caster_collision'>
      <origin xyz="-0.200 0 -0.075" rpy=" 0 0 0"/>
      <geometry>
        <sphere radius="${castor_r - 0.0001}"/>
      </geometry>
    </collision>

    <visual name='back_caster_visual'>
      <origin xyz="-0.200 0 -0.075" rpy=" 0 0 0"/>
      <geometry>
        <sphere radius="${castor_r}"/>
      </geometry>
    </visual>

    <collision name='front_caster_collision'>
      <origin xyz="0.200 0 -0.075" rpy=" 0 0 0"/>
      <geometry>
        <sphere radius="${castor_r - 0.0001}"/>
      </geometry>
    </collision>

    <visual name='front_caster_visual'>
      <origin xyz="0.200 0 -0.075" rpy=" 0 0 0"/>
      <geometry>
        <sphere radius="${castor_r}"/>
      </geometry>
    </visual>

  </link>

  <link name="left_wheel">
    <collision name="left_wheel_collision">
      <origin xyz="0 0 0" rpy="0 1.5707 1.5707"/>
      <geometry>
        <cylinder radius="${wheel_r}" length="${wheel_l}"/>
      </geometry>
    </collision>
    <inertial>
      <mass value="5.0"/>
      <origin xyz="0 0 0" rpy="0 1.5707 1.5707"/>
      <inertia
          ixx="0.1" ixy="0" ixz="0"
          iyy="0.1" iyz="0"
          izz="0.1"
      />
    </inertial>
    <visual name="left_wheel_visual">
      <origin xyz="0 0 0" rpy=" 0 1.5707 1.5707"/>
      <geometry>
        <cylinder radius="${wheel_r}" length="${wheel_l}"/>
      </geometry>
    </visual>
  </link>

  <link name="right_wheel">
    <collision name="right_wheel_collision">
      <origin xyz="0 0 0" rpy="0 1.5707 1.5707"/>
      <geometry>
        <cylinder radius="${wheel_r}" length="${wheel_l}"/>
      </geometry>
    </collision>
    <inertial>
      <mass value="5.0"/>
      <origin xyz="0 0 0" rpy="0 1.5707 1.5707"/>
      <inertia
          ixx="0.1" ixy="0" ixz="0"
          iyy="0.1" iyz="0"
          izz="0.1"
      />
    </inertial>
    <visual name="right_wheel_visual">
      <origin xyz="0 0 0" rpy=" 0 1.5707 1.5707"/>
      <geometry>
        <cylinder radius="${wheel_r}" length="${wheel_l}"/>
      </geometry>
    </visual>
  </link>
	
  <joint type="continuous" name="left_wheel_hinge">
    <origin xyz="0 0.205 0" rpy="0 0 0"/>
    <child link="left_wheel"/>
    <parent link="chassis"/>
    <axis xyz="0 1 0" rpy="0 0 0"/>
    <limit effort="10000" velocity="1000"/>
    <dynamics damping="0.0" friction="1.0"/>
  </joint>

  <joint type="continuous" name="right_wheel_hinge">
    <origin xyz="0 -0.205 0" rpy="0 0 0"/>
    <child link="right_wheel"/>
    <parent link="chassis"/>
    <axis xyz="0 1 0" rpy="0 0 0"/>
    <limit effort="10000" velocity="1000"/>
    <dynamics damping="0.0" friction="1.0"/>
  </joint>

  <link name="camera">
    <collision name="camera_collision">
      <origin xyz="0 0 0" rpy="0 0 0"/>
      <geometry>
        <box size="0.05 0.05 0.05"/>
      </geometry>
    </collision>
    <inertial>
      <mass value="0.1"/>
      <origin xyz="0.05 0.05 0.05" rpy="0 0 0"/>
      <inertia
          ixx="1e-6" ixy="0" ixz="0"
          iyy="1e-6" iyz="0"
          izz="1e-6"
      />
    </inertial>
    <visual name="camera_visual">
      <origin xyz="0 0 0" rpy="0 0 0"/>
      <geometry>
        <box size="0.05 0.05 0.05"/>
      </geometry>
    </visual>
  </link>

  <joint type="fixed" name="camera_joint">
    <origin xyz="0.2 0 0" rpy="0 0 0"/>
    <child link="camera"/>
    <parent link="chassis"/>
    <axis xyz="0 1 0" rpy="0 0 0"/>
  </joint>

  <joint name="camera_optical_joint" type="fixed">
    <origin xyz="0 0 0" rpy="-1.5707 0 -1.5707"/>
    <parent link="camera"/>
    <child link="camera_link_optical"/>
  </joint>

  <link name="camera_link_optical">
  </link>

  <link name="hokuyo">
    <collision name="hokuyo_collision">
      <origin xyz="0 0 0" rpy="0 0 0"/>
      <geometry>
        <box size="0.1 0.1 0.1"/>
      </geometry>
    </collision>
    <inertial>
      <mass value="1e-5"/>
      <inertia
          ixx="1e-6" ixy="0" ixz="0"
          iyy="1e-6" iyz="0"
          izz="1e-6"
      />
    </inertial>
    <visual name="hokuyo_visual">
      <origin xyz="0 0 0" rpy="0 0 0"/>
      <geometry>
        <mesh filename="package://my_robot/meshes/hokuyo.dae"/>
      </geometry>
    </visual>
  </link>

  <joint type="fixed" name="hokuyo_joint">
    <origin xyz="0.225 0 0.125" rpy="0 0 0"/>
    <child link="hokuyo"/>
    <parent link="chassis"/>
    <axis xyz="0 1 0" rpy="0 0 0"/>
  </joint>

  <joint type="fixed" name="rear_wing_joint">
    <origin xyz="-0.225 0 0.125" rpy="0 0 0"/>
    <child link="rear_wing"/>
    <parent link="chassis"/>
    <axis xyz="0 1 0" rpy="0 0 0"/>
  </joint>

  <link name='rear_wing'>
    <inertial>
      <mass value="0.5"/>
      <origin xyz="0.0 0 0" rpy="0 0 0"/>
      <inertia
          ixx="0.1" ixy="0" ixz="0"
          iyy="0.1" iyz="0"
          izz="0.1"
      />
    </inertial>
    <collision name='collision'>
      <origin xyz="0 0 0" rpy=" 0 0 0"/> 
      <geometry>
        <box size="${rear_wing_l} ${rear_wing_w} ${rear_wing_h}"/>
      </geometry>
    </collision>
    <visual name='chassis_visual'>
      <origin xyz="0 0 0" rpy=" 0 0 0"/>
      <geometry>
        <box size="${rear_wing_l} ${rear_wing_w} ${rear_wing_h}"/>
      </geometry>
    </visual>
  </link>

  <!-- Defining the colors of my Ferrari -->	
  <gazebo reference="left_wheel">
    <material>Gazebo/Black</material>
  </gazebo>
  <gazebo reference="right_wheel">
    <material>Gazebo/Black</material>
  </gazebo>
  <gazebo reference="chassis">
    <material>Gazebo/Red</material>
  </gazebo>
  <gazebo reference="rear_wing">
    <material>Gazebo/Red</material>
  </gazebo>
  <gazebo reference="hokuyo">
    <material>Gazebo/Yellow</material>
  </gazebo>
  <gazebo reference="camera">
    <material>Gazebo/Orange</material>
  </gazebo>

</robot>
